<?xml version="1.0" encoding="utf-8"?>
<!-- This URDF was automatically created by SolidWorks to URDF Exporter! Originally created by Stephen Brawner (brawner@gmail.com) 
     Commit Version: 1.6.0-4-g7f85cfe  Build Version: 1.6.7995.38578
     For more information, please see http://wiki.ros.org/sw_urdf_exporter -->
<robot
  name="robot_part2">
  <link
    name="base_link">
    <inertial>
      <origin
        xyz="-0.0041167 5.0661E-05 0.055243"
        rpy="0 0 0" />
      <mass
        value="1.4917" />
      <inertia
        ixx="0.0024753"
        ixy="1.6253E-07"
        ixz="0.00015354"
        iyy="0.0047624"
        iyz="-1.0939E-06"
        izz="0.0067446" />
    </inertial>
    <visual>
      <origin
        xyz="0 0 0"
        rpy="0 0 0" />
      <geometry>
        <mesh
          filename="package://robot_part2/meshes/base_link.STL" />
      </geometry>
      <material
        name="">
        <color
          rgba="0.79216 0.81961 0.93333 1" />
      </material>
    </visual>
    <collision>
      <origin
        xyz="0 0 0"
        rpy="0 0 0" />
      <geometry>
        <mesh
          filename="package://robot_part2/meshes/base_link.STL" />
      </geometry>
    </collision>
  </link>
  <link
    name="left">
    <inertial>
      <origin
        xyz="-1.5318E-08 -7.4504E-09 -0.012822"
        rpy="0 0 0" />
      <mass
        value="0.30996" />
      <inertia
        ixx="0.00053464"
        ixy="-1.2152E-10"
        ixz="1.4351E-11"
        iyy="0.00053464"
        iyz="7.5703E-12"
        izz="0.0010312" />
    </inertial>
    <visual>
      <origin
        xyz="0 0 0"
        rpy="0 0 0" />
      <geometry>
        <mesh
          filename="package://robot_part2/meshes/left.STL" />
      </geometry>
      <material
        name="">
        <color
          rgba="0.79216 0.81961 0.93333 1" />
      </material>
    </visual>
    <collision>
      <origin
        xyz="0 0 0"
        rpy="0 0 0" />
      <geometry>
        <mesh
          filename="package://robot_part2/meshes/left.STL" />
      </geometry>
    </collision>
  </link>
  <joint
    name="left"
    type="continuous">
    <origin
      xyz="-0.097381 0.145 0.0085"
      rpy="-1.5708 0 0" />
    <parent
      link="base_link" />
    <child
      link="left" />
    <axis
      xyz="0 0 1" />
    <limit
      effort="100"
      velocity="100" />
    <dynamics
      damping="0.1"
      friction="0.1" />
  </joint>
  <link
    name="right">
    <inertial>
      <origin
        xyz="8.8298E-09 1.4566E-08 0.0053216"
        rpy="0 0 0" />
      <mass
        value="0.30996" />
      <inertia
        ixx="0.00053464"
        ixy="-1.3827E-10"
        ixz="8.8601E-12"
        iyy="0.00053464"
        iyz="1.3593E-11"
        izz="0.0010312" />
    </inertial>
    <visual>
      <origin
        xyz="0 0 0"
        rpy="0 0 0" />
      <geometry>
        <mesh
          filename="package://robot_part2/meshes/right.STL" />
      </geometry>
      <material
        name="">
        <color
          rgba="0.79216 0.81961 0.93333 1" />
      </material>
    </visual>
    <collision>
      <origin
        xyz="0 0 0"
        rpy="0 0 0" />
      <geometry>
        <mesh
          filename="package://robot_part2/meshes/right.STL" />
      </geometry>
    </collision>
  </link>
  <joint
    name="right"
    type="continuous">
    <origin
      xyz="-0.097381 -0.1375 0.0085"
      rpy="1.5708 0 -3.1416" />
    <parent
      link="base_link" />
    <child
      link="right" />
    <axis
      xyz="0 0 -1" />
    <limit
      effort="100"
      velocity="100" />
    <dynamics
      damping="0.1"
      friction="0.1" />
  </joint>
  <link
    name="conquay">
    <inertial>
      <origin
        xyz="-0.0067376 -9.0019E-09 0.010834"
        rpy="0 0 0" />
      <mass
        value="0.0019837" />
      <inertia
        ixx="2.7268E-07"
        ixy="-1.4459E-12"
        ixz="8.356E-08"
        iyy="3.0637E-07"
        iyz="1.3524E-12"
        izz="2.7057E-07" />
    </inertial>
    <visual>
      <origin
        xyz="0 0 0"
        rpy="0 0 0" />
      <geometry>
        <mesh
          filename="package://robot_part2/meshes/conquay.STL" />
      </geometry>
      <material
        name="">
        <color
          rgba="0.79216 0.81961 0.93333 1" />
      </material>
    </visual>
    <collision>
      <origin
        xyz="0 0 0"
        rpy="0 0 0" />
      <geometry>
        <mesh
          filename="package://robot_part2/meshes/conquay.STL" />
      </geometry>
    </collision>
  </link>
  <joint
    name="conquay"
    type="continuous">
    <origin
      xyz="0.080203 0 -0.008"
      rpy="3.1416 0 0" />
    <parent
      link="base_link" />
    <child
      link="conquay" />
    <axis
      xyz="0 0 -1" />
    <limit
      effort="100"
      velocity="100" />
    <dynamics
      damping="0.1"
      friction="0.1" />
  </joint>
  <link
    name="miniwheel">
    <inertial>
      <origin
        xyz="5.3991E-11 9.4611E-11 -4.997E-13"
        rpy="0 0 0" />
      <mass
        value="0.007535" />
      <inertia
        ixx="1.18E-06"
        ixy="-1.46E-16"
        ixz="-1.9283E-16"
        iyy="1.18E-06"
        iyz="-7.274E-17"
        izz="2.2175E-06" />
    </inertial>
    <visual>
      <origin
        xyz="0 0 0"
        rpy="0 0 0" />
      <geometry>
        <mesh
          filename="package://robot_part2/meshes/miniwheel.STL" />
      </geometry>
      <material
        name="">
        <color
          rgba="0.79216 0.81961 0.93333 1" />
      </material>
    </visual>
    <collision>
      <origin
        xyz="0 0 0"
        rpy="0 0 0" />
      <geometry>
        <mesh
          filename="package://robot_part2/meshes/miniwheel.STL" />
      </geometry>
    </collision>
  </link>
  <joint
    name="miniwheel"
    type="continuous">
    <origin
      xyz="-0.015015 0 0.027"
      rpy="1.5708 -1.5708 0" />
    <parent
      link="conquay" />
    <child
      link="miniwheel" />
    <axis
      xyz="0 0 1" />
    <limit
      effort="100"
      velocity="100" />
    <dynamics
      damping="0.1"
      friction="0.1" />
  </joint>
</robot>